2018-02-06 21:08:46,935 ERROR: Exception on /api/Rob/posts [GET] [in /Users/rlheureu/Coding/microblog-0.15/venv/lib/python2.7/site-packages/flask/app.py:1560]
Traceback (most recent call last):
  File "/Users/rlheureu/Coding/microblog-0.15/venv/lib/python2.7/site-packages/flask/app.py", line 1982, in wsgi_app
    response = self.full_dispatch_request()
  File "/Users/rlheureu/Coding/microblog-0.15/venv/lib/python2.7/site-packages/flask/app.py", line 1614, in full_dispatch_request
    rv = self.handle_user_exception(e)
  File "/Users/rlheureu/Coding/microblog-0.15/venv/lib/python2.7/site-packages/flask/app.py", line 1517, in handle_user_exception
    reraise(exc_type, exc_value, tb)
  File "/Users/rlheureu/Coding/microblog-0.15/venv/lib/python2.7/site-packages/flask/app.py", line 1612, in full_dispatch_request
    rv = self.dispatch_request()
  File "/Users/rlheureu/Coding/microblog-0.15/venv/lib/python2.7/site-packages/flask/app.py", line 1598, in dispatch_request
    return self.view_functions[rule.endpoint](**req.view_args)
  File "/Users/rlheureu/Coding/microblog-0.15/app/api/posts.py", line 31, in get_user_posts
    data = Post.to_collection_dict(Post.query.filter_by(user_id=user.id), page, per_page, 'api.get_user_posts', username=user.username)
  File "/Users/rlheureu/Coding/microblog-0.15/app/models.py", line 16, in to_collection_dict
    'items': [item.to_dict() for item in resources.items],
  File "/Users/rlheureu/Coding/microblog-0.15/app/models.py", line 240, in to_dict
    'posts': url_for('api.get_user_posts', id=self.user_id)
  File "/Users/rlheureu/Coding/microblog-0.15/venv/lib/python2.7/site-packages/flask/helpers.py", line 333, in url_for
    return appctx.app.handle_url_build_error(error, endpoint, values)
  File "/Users/rlheureu/Coding/microblog-0.15/venv/lib/python2.7/site-packages/flask/app.py", line 1805, in handle_url_build_error
    reraise(exc_type, exc_value, tb)
  File "/Users/rlheureu/Coding/microblog-0.15/venv/lib/python2.7/site-packages/flask/helpers.py", line 323, in url_for
    force_external=external)
  File "/Users/rlheureu/Coding/microblog-0.15/venv/lib/python2.7/site-packages/werkzeug/routing.py", line 1768, in build
    raise BuildError(endpoint, values, method, self)
BuildError: Could not build url for endpoint 'api.get_user_posts' with values ['id']. Did you forget to specify values ['username']?
2018-02-06 21:12:30,236 INFO: Microblog startup [in /Users/rlheureu/Coding/microblog-0.15/app/__init__.py:85]
2018-02-06 21:12:34,024 ERROR: Exception on /api/Rob/posts [GET] [in /Users/rlheureu/Coding/microblog-0.15/venv/lib/python2.7/site-packages/flask/app.py:1560]
Traceback (most recent call last):
  File "/Users/rlheureu/Coding/microblog-0.15/venv/lib/python2.7/site-packages/flask/app.py", line 1982, in wsgi_app
    response = self.full_dispatch_request()
  File "/Users/rlheureu/Coding/microblog-0.15/venv/lib/python2.7/site-packages/flask/app.py", line 1614, in full_dispatch_request
    rv = self.handle_user_exception(e)
  File "/Users/rlheureu/Coding/microblog-0.15/venv/lib/python2.7/site-packages/flask/app.py", line 1517, in handle_user_exception
    reraise(exc_type, exc_value, tb)
  File "/Users/rlheureu/Coding/microblog-0.15/venv/lib/python2.7/site-packages/flask/app.py", line 1612, in full_dispatch_request
    rv = self.dispatch_request()
  File "/Users/rlheureu/Coding/microblog-0.15/venv/lib/python2.7/site-packages/flask/app.py", line 1598, in dispatch_request
    return self.view_functions[rule.endpoint](**req.view_args)
  File "/Users/rlheureu/Coding/microblog-0.15/app/api/posts.py", line 31, in get_user_posts
    data = Post.to_collection_dict(Post.query.filter_by(user_id=user.id), page, per_page, 'api.get_user_posts', username=user.username)
  File "/Users/rlheureu/Coding/microblog-0.15/app/models.py", line 16, in to_collection_dict
    'items': [item.to_dict() for item in resources.items],
  File "/Users/rlheureu/Coding/microblog-0.15/app/models.py", line 240, in to_dict
    'posts': url_for('api.get_user_posts', username=self.username)
AttributeError: 'Post' object has no attribute 'username'
2018-02-07 08:05:51,874 INFO: Microblog startup [in /Users/rlheureu/Coding/microblog-0.15/app/__init__.py:85]
2018-02-07 08:05:58,510 ERROR: Exception on /api/Rob/posts [GET] [in /Users/rlheureu/Coding/microblog-0.15/venv/lib/python2.7/site-packages/flask/app.py:1560]
Traceback (most recent call last):
  File "/Users/rlheureu/Coding/microblog-0.15/venv/lib/python2.7/site-packages/flask/app.py", line 1982, in wsgi_app
    response = self.full_dispatch_request()
  File "/Users/rlheureu/Coding/microblog-0.15/venv/lib/python2.7/site-packages/flask/app.py", line 1614, in full_dispatch_request
    rv = self.handle_user_exception(e)
  File "/Users/rlheureu/Coding/microblog-0.15/venv/lib/python2.7/site-packages/flask/app.py", line 1517, in handle_user_exception
    reraise(exc_type, exc_value, tb)
  File "/Users/rlheureu/Coding/microblog-0.15/venv/lib/python2.7/site-packages/flask/app.py", line 1612, in full_dispatch_request
    rv = self.dispatch_request()
  File "/Users/rlheureu/Coding/microblog-0.15/venv/lib/python2.7/site-packages/flask/app.py", line 1598, in dispatch_request
    return self.view_functions[rule.endpoint](**req.view_args)
TypeError: get_user_posts() got an unexpected keyword argument 'username'
2018-02-07 08:37:17,448 INFO: Microblog startup [in /Users/rlheureu/Coding/microblog-0.15/app/__init__.py:85]
2018-02-07 08:37:30,212 ERROR: Exception on /api/1/posts [GET] [in /Users/rlheureu/Coding/microblog-0.15/venv/lib/python2.7/site-packages/flask/app.py:1560]
Traceback (most recent call last):
  File "/Users/rlheureu/Coding/microblog-0.15/venv/lib/python2.7/site-packages/flask/app.py", line 1982, in wsgi_app
    response = self.full_dispatch_request()
  File "/Users/rlheureu/Coding/microblog-0.15/venv/lib/python2.7/site-packages/flask/app.py", line 1614, in full_dispatch_request
    rv = self.handle_user_exception(e)
  File "/Users/rlheureu/Coding/microblog-0.15/venv/lib/python2.7/site-packages/flask/app.py", line 1517, in handle_user_exception
    reraise(exc_type, exc_value, tb)
  File "/Users/rlheureu/Coding/microblog-0.15/venv/lib/python2.7/site-packages/flask/app.py", line 1612, in full_dispatch_request
    rv = self.dispatch_request()
  File "/Users/rlheureu/Coding/microblog-0.15/venv/lib/python2.7/site-packages/flask/app.py", line 1598, in dispatch_request
    return self.view_functions[rule.endpoint](**req.view_args)
  File "/Users/rlheureu/Coding/microblog-0.15/app/api/posts.py", line 22, in get_user_posts
    user = User.query.filter_by(user_id=user.id).first()
UnboundLocalError: local variable 'user' referenced before assignment
2018-02-07 08:38:03,733 INFO: Microblog startup [in /Users/rlheureu/Coding/microblog-0.15/app/__init__.py:85]
2018-02-07 08:38:06,111 ERROR: Exception on /api/1/posts [GET] [in /Users/rlheureu/Coding/microblog-0.15/venv/lib/python2.7/site-packages/flask/app.py:1560]
Traceback (most recent call last):
  File "/Users/rlheureu/Coding/microblog-0.15/venv/lib/python2.7/site-packages/flask/app.py", line 1982, in wsgi_app
    response = self.full_dispatch_request()
  File "/Users/rlheureu/Coding/microblog-0.15/venv/lib/python2.7/site-packages/flask/app.py", line 1614, in full_dispatch_request
    rv = self.handle_user_exception(e)
  File "/Users/rlheureu/Coding/microblog-0.15/venv/lib/python2.7/site-packages/flask/app.py", line 1517, in handle_user_exception
    reraise(exc_type, exc_value, tb)
  File "/Users/rlheureu/Coding/microblog-0.15/venv/lib/python2.7/site-packages/flask/app.py", line 1612, in full_dispatch_request
    rv = self.dispatch_request()
  File "/Users/rlheureu/Coding/microblog-0.15/venv/lib/python2.7/site-packages/flask/app.py", line 1598, in dispatch_request
    return self.view_functions[rule.endpoint](**req.view_args)
  File "/Users/rlheureu/Coding/microblog-0.15/app/api/posts.py", line 22, in get_user_posts
    user = User.query.filter_by(user_id=id).first()
  File "/Users/rlheureu/Coding/microblog-0.15/venv/lib/python2.7/site-packages/sqlalchemy/orm/query.py", line 1562, in filter_by
    for key, value in kwargs.items()]
  File "/Users/rlheureu/Coding/microblog-0.15/venv/lib/python2.7/site-packages/sqlalchemy/orm/base.py", line 383, in _entity_descriptor
    (description, key)
InvalidRequestError: Entity '<class 'app.models.User'>' has no property 'user_id'
2018-02-07 08:38:15,535 INFO: Microblog startup [in /Users/rlheureu/Coding/microblog-0.15/app/__init__.py:85]
2018-02-07 08:38:41,461 INFO: Microblog startup [in /Users/rlheureu/Coding/microblog-0.15/app/__init__.py:85]
2018-02-07 08:39:17,518 INFO: Microblog startup [in /Users/rlheureu/Coding/microblog-0.15/app/__init__.py:85]
