2018-02-06 16:45:13,840 ERROR: Exception on /api/posts [POST] [in /Users/rlheureu/Coding/microblog-0.15/venv/lib/python2.7/site-packages/flask/app.py:1560]
Traceback (most recent call last):
  File "/Users/rlheureu/Coding/microblog-0.15/venv/lib/python2.7/site-packages/flask/app.py", line 1982, in wsgi_app
    response = self.full_dispatch_request()
  File "/Users/rlheureu/Coding/microblog-0.15/venv/lib/python2.7/site-packages/flask/app.py", line 1614, in full_dispatch_request
    rv = self.handle_user_exception(e)
  File "/Users/rlheureu/Coding/microblog-0.15/venv/lib/python2.7/site-packages/flask/app.py", line 1517, in handle_user_exception
    reraise(exc_type, exc_value, tb)
  File "/Users/rlheureu/Coding/microblog-0.15/venv/lib/python2.7/site-packages/flask/app.py", line 1612, in full_dispatch_request
    rv = self.dispatch_request()
  File "/Users/rlheureu/Coding/microblog-0.15/venv/lib/python2.7/site-packages/flask/app.py", line 1598, in dispatch_request
    return self.view_functions[rule.endpoint](**req.view_args)
  File "/Users/rlheureu/Coding/microblog-0.15/venv/lib/python2.7/site-packages/flask_httpauth.py", line 93, in decorated
    return f(*args, **kwargs)
  File "/Users/rlheureu/Coding/microblog-0.15/app/api/posts.py", line 51, in create_post
    post.from_dict(data, new_post=True)
  File "/Users/rlheureu/Coding/microblog-0.15/app/models.py", line 248, in from_dict
    setattr(self, field, data[field])
  File "/Users/rlheureu/Coding/microblog-0.15/venv/lib/python2.7/site-packages/sqlalchemy/orm/attributes.py", line 224, in __set__
    instance_dict(instance), value, None)
  File "/Users/rlheureu/Coding/microblog-0.15/venv/lib/python2.7/site-packages/sqlalchemy/orm/attributes.py", line 812, in set
    value = self.fire_replace_event(state, dict_, value, old, initiator)
  File "/Users/rlheureu/Coding/microblog-0.15/venv/lib/python2.7/site-packages/sqlalchemy/orm/attributes.py", line 834, in fire_replace_event
    self._replace_token or self._init_append_or_replace_token())
  File "/Users/rlheureu/Coding/microblog-0.15/venv/lib/python2.7/site-packages/sqlalchemy/orm/attributes.py", line 1175, in emit_backref_from_scalar_set_event
    child_state, child_dict = instance_state(child),\
AttributeError: 'int' object has no attribute '_sa_instance_state'
2018-02-06 16:47:38,463 INFO: Microblog startup [in /Users/rlheureu/Coding/microblog-0.15/app/__init__.py:85]
2018-02-06 16:47:52,767 ERROR: Exception on /api/posts [POST] [in /Users/rlheureu/Coding/microblog-0.15/venv/lib/python2.7/site-packages/flask/app.py:1560]
Traceback (most recent call last):
  File "/Users/rlheureu/Coding/microblog-0.15/venv/lib/python2.7/site-packages/flask/app.py", line 1982, in wsgi_app
    response = self.full_dispatch_request()
  File "/Users/rlheureu/Coding/microblog-0.15/venv/lib/python2.7/site-packages/flask/app.py", line 1614, in full_dispatch_request
    rv = self.handle_user_exception(e)
  File "/Users/rlheureu/Coding/microblog-0.15/venv/lib/python2.7/site-packages/flask/app.py", line 1517, in handle_user_exception
    reraise(exc_type, exc_value, tb)
  File "/Users/rlheureu/Coding/microblog-0.15/venv/lib/python2.7/site-packages/flask/app.py", line 1612, in full_dispatch_request
    rv = self.dispatch_request()
  File "/Users/rlheureu/Coding/microblog-0.15/venv/lib/python2.7/site-packages/flask/app.py", line 1598, in dispatch_request
    return self.view_functions[rule.endpoint](**req.view_args)
  File "/Users/rlheureu/Coding/microblog-0.15/venv/lib/python2.7/site-packages/flask_httpauth.py", line 93, in decorated
    return f(*args, **kwargs)
  File "/Users/rlheureu/Coding/microblog-0.15/app/api/posts.py", line 51, in create_post
    post.from_dict(data, new_post=True)
  File "/Users/rlheureu/Coding/microblog-0.15/app/models.py", line 248, in from_dict
    setattr(self, field, data[field])
  File "/Users/rlheureu/Coding/microblog-0.15/venv/lib/python2.7/site-packages/sqlalchemy/orm/attributes.py", line 224, in __set__
    instance_dict(instance), value, None)
  File "/Users/rlheureu/Coding/microblog-0.15/venv/lib/python2.7/site-packages/sqlalchemy/orm/attributes.py", line 812, in set
    value = self.fire_replace_event(state, dict_, value, old, initiator)
  File "/Users/rlheureu/Coding/microblog-0.15/venv/lib/python2.7/site-packages/sqlalchemy/orm/attributes.py", line 834, in fire_replace_event
    self._replace_token or self._init_append_or_replace_token())
  File "/Users/rlheureu/Coding/microblog-0.15/venv/lib/python2.7/site-packages/sqlalchemy/orm/attributes.py", line 1175, in emit_backref_from_scalar_set_event
    child_state, child_dict = instance_state(child),\
AttributeError: 'int' object has no attribute '_sa_instance_state'
2018-02-06 17:16:34,816 INFO: Microblog startup [in /Users/rlheureu/Coding/microblog-0.15/app/__init__.py:85]
2018-02-06 17:16:41,127 ERROR: Exception on /api/posts [POST] [in /Users/rlheureu/Coding/microblog-0.15/venv/lib/python2.7/site-packages/flask/app.py:1560]
Traceback (most recent call last):
  File "/Users/rlheureu/Coding/microblog-0.15/venv/lib/python2.7/site-packages/flask/app.py", line 1982, in wsgi_app
    response = self.full_dispatch_request()
  File "/Users/rlheureu/Coding/microblog-0.15/venv/lib/python2.7/site-packages/flask/app.py", line 1614, in full_dispatch_request
    rv = self.handle_user_exception(e)
  File "/Users/rlheureu/Coding/microblog-0.15/venv/lib/python2.7/site-packages/flask/app.py", line 1517, in handle_user_exception
    reraise(exc_type, exc_value, tb)
  File "/Users/rlheureu/Coding/microblog-0.15/venv/lib/python2.7/site-packages/flask/app.py", line 1612, in full_dispatch_request
    rv = self.dispatch_request()
  File "/Users/rlheureu/Coding/microblog-0.15/venv/lib/python2.7/site-packages/flask/app.py", line 1598, in dispatch_request
    return self.view_functions[rule.endpoint](**req.view_args)
  File "/Users/rlheureu/Coding/microblog-0.15/venv/lib/python2.7/site-packages/flask_httpauth.py", line 93, in decorated
    return f(*args, **kwargs)
  File "/Users/rlheureu/Coding/microblog-0.15/app/api/posts.py", line 51, in create_post
    post.from_dict(data, new_post=True)
  File "/Users/rlheureu/Coding/microblog-0.15/app/models.py", line 248, in from_dict
    setattr(self, field, data[field])
  File "/Users/rlheureu/Coding/microblog-0.15/venv/lib/python2.7/site-packages/sqlalchemy/orm/attributes.py", line 224, in __set__
    instance_dict(instance), value, None)
  File "/Users/rlheureu/Coding/microblog-0.15/venv/lib/python2.7/site-packages/sqlalchemy/orm/attributes.py", line 812, in set
    value = self.fire_replace_event(state, dict_, value, old, initiator)
  File "/Users/rlheureu/Coding/microblog-0.15/venv/lib/python2.7/site-packages/sqlalchemy/orm/attributes.py", line 834, in fire_replace_event
    self._replace_token or self._init_append_or_replace_token())
  File "/Users/rlheureu/Coding/microblog-0.15/venv/lib/python2.7/site-packages/sqlalchemy/orm/attributes.py", line 1175, in emit_backref_from_scalar_set_event
    child_state, child_dict = instance_state(child),\
AttributeError: 'int' object has no attribute '_sa_instance_state'
2018-02-06 17:19:24,846 ERROR: Exception on /api/posts/1 [GET] [in /Users/rlheureu/Coding/microblog-0.15/venv/lib/python2.7/site-packages/flask/app.py:1560]
Traceback (most recent call last):
  File "/Users/rlheureu/Coding/microblog-0.15/venv/lib/python2.7/site-packages/flask/app.py", line 1982, in wsgi_app
    response = self.full_dispatch_request()
  File "/Users/rlheureu/Coding/microblog-0.15/venv/lib/python2.7/site-packages/flask/app.py", line 1614, in full_dispatch_request
    rv = self.handle_user_exception(e)
  File "/Users/rlheureu/Coding/microblog-0.15/venv/lib/python2.7/site-packages/flask/app.py", line 1517, in handle_user_exception
    reraise(exc_type, exc_value, tb)
  File "/Users/rlheureu/Coding/microblog-0.15/venv/lib/python2.7/site-packages/flask/app.py", line 1612, in full_dispatch_request
    rv = self.dispatch_request()
  File "/Users/rlheureu/Coding/microblog-0.15/venv/lib/python2.7/site-packages/flask/app.py", line 1598, in dispatch_request
    return self.view_functions[rule.endpoint](**req.view_args)
  File "/Users/rlheureu/Coding/microblog-0.15/app/api/posts.py", line 10, in get_post
    return jsonify(Post.query.get_or_404(id).to_dict())
  File "/Users/rlheureu/Coding/microblog-0.15/app/models.py", line 240, in to_dict
    'posts': url_for('api.get_user_posts', id=self.user_id)
  File "/Users/rlheureu/Coding/microblog-0.15/venv/lib/python2.7/site-packages/flask/helpers.py", line 333, in url_for
    return appctx.app.handle_url_build_error(error, endpoint, values)
  File "/Users/rlheureu/Coding/microblog-0.15/venv/lib/python2.7/site-packages/flask/app.py", line 1805, in handle_url_build_error
    reraise(exc_type, exc_value, tb)
  File "/Users/rlheureu/Coding/microblog-0.15/venv/lib/python2.7/site-packages/flask/helpers.py", line 323, in url_for
    force_external=external)
  File "/Users/rlheureu/Coding/microblog-0.15/venv/lib/python2.7/site-packages/werkzeug/routing.py", line 1768, in build
    raise BuildError(endpoint, values, method, self)
BuildError: Could not build url for endpoint 'api.get_user_posts' with values ['id']. Did you forget to specify values ['username']?
