2018-02-06 16:01:02,259 ERROR: Exception on /api/posts [POST] [in /Users/rlheureu/Coding/microblog-0.15/venv/lib/python2.7/site-packages/flask/app.py:1560]
Traceback (most recent call last):
  File "/Users/rlheureu/Coding/microblog-0.15/venv/lib/python2.7/site-packages/flask/app.py", line 1982, in wsgi_app
    response = self.full_dispatch_request()
  File "/Users/rlheureu/Coding/microblog-0.15/venv/lib/python2.7/site-packages/flask/app.py", line 1614, in full_dispatch_request
    rv = self.handle_user_exception(e)
  File "/Users/rlheureu/Coding/microblog-0.15/venv/lib/python2.7/site-packages/flask/app.py", line 1517, in handle_user_exception
    reraise(exc_type, exc_value, tb)
  File "/Users/rlheureu/Coding/microblog-0.15/venv/lib/python2.7/site-packages/flask/app.py", line 1612, in full_dispatch_request
    rv = self.dispatch_request()
  File "/Users/rlheureu/Coding/microblog-0.15/venv/lib/python2.7/site-packages/flask/app.py", line 1598, in dispatch_request
    return self.view_functions[rule.endpoint](**req.view_args)
  File "/Users/rlheureu/Coding/microblog-0.15/venv/lib/python2.7/site-packages/flask_httpauth.py", line 93, in decorated
    return f(*args, **kwargs)
  File "/Users/rlheureu/Coding/microblog-0.15/app/api/posts.py", line 46, in create_post
    if user.id != data['user_id']:
NameError: global name 'user' is not defined
2018-02-06 16:01:24,460 INFO: Microblog startup [in /Users/rlheureu/Coding/microblog-0.15/app/__init__.py:85]
2018-02-06 16:01:29,001 ERROR: Exception on /api/posts [POST] [in /Users/rlheureu/Coding/microblog-0.15/venv/lib/python2.7/site-packages/flask/app.py:1560]
Traceback (most recent call last):
  File "/Users/rlheureu/Coding/microblog-0.15/venv/lib/python2.7/site-packages/flask/app.py", line 1982, in wsgi_app
    response = self.full_dispatch_request()
  File "/Users/rlheureu/Coding/microblog-0.15/venv/lib/python2.7/site-packages/flask/app.py", line 1614, in full_dispatch_request
    rv = self.handle_user_exception(e)
  File "/Users/rlheureu/Coding/microblog-0.15/venv/lib/python2.7/site-packages/flask/app.py", line 1517, in handle_user_exception
    reraise(exc_type, exc_value, tb)
  File "/Users/rlheureu/Coding/microblog-0.15/venv/lib/python2.7/site-packages/flask/app.py", line 1612, in full_dispatch_request
    rv = self.dispatch_request()
  File "/Users/rlheureu/Coding/microblog-0.15/venv/lib/python2.7/site-packages/flask/app.py", line 1598, in dispatch_request
    return self.view_functions[rule.endpoint](**req.view_args)
  File "/Users/rlheureu/Coding/microblog-0.15/venv/lib/python2.7/site-packages/flask_httpauth.py", line 93, in decorated
    return f(*args, **kwargs)
  File "/Users/rlheureu/Coding/microblog-0.15/app/api/posts.py", line 46, in create_post
    if user.id != data['user_id']:
KeyError: 'user_id'
2018-02-06 16:02:14,967 INFO: Microblog startup [in /Users/rlheureu/Coding/microblog-0.15/app/__init__.py:85]
2018-02-06 16:02:21,546 ERROR: Exception on /api/posts [POST] [in /Users/rlheureu/Coding/microblog-0.15/venv/lib/python2.7/site-packages/flask/app.py:1560]
Traceback (most recent call last):
  File "/Users/rlheureu/Coding/microblog-0.15/venv/lib/python2.7/site-packages/flask/app.py", line 1982, in wsgi_app
    response = self.full_dispatch_request()
  File "/Users/rlheureu/Coding/microblog-0.15/venv/lib/python2.7/site-packages/flask/app.py", line 1614, in full_dispatch_request
    rv = self.handle_user_exception(e)
  File "/Users/rlheureu/Coding/microblog-0.15/venv/lib/python2.7/site-packages/flask/app.py", line 1517, in handle_user_exception
    reraise(exc_type, exc_value, tb)
  File "/Users/rlheureu/Coding/microblog-0.15/venv/lib/python2.7/site-packages/flask/app.py", line 1612, in full_dispatch_request
    rv = self.dispatch_request()
  File "/Users/rlheureu/Coding/microblog-0.15/venv/lib/python2.7/site-packages/flask/app.py", line 1598, in dispatch_request
    return self.view_functions[rule.endpoint](**req.view_args)
  File "/Users/rlheureu/Coding/microblog-0.15/venv/lib/python2.7/site-packages/flask_httpauth.py", line 93, in decorated
    return f(*args, **kwargs)
  File "/Users/rlheureu/Coding/microblog-0.15/app/api/posts.py", line 49, in create_post
    data = setattr(self,['user_id'], user_id)
NameError: global name 'self' is not defined
2018-02-06 16:03:50,610 INFO: Microblog startup [in /Users/rlheureu/Coding/microblog-0.15/app/__init__.py:85]
2018-02-06 16:03:57,671 ERROR: Exception on /api/posts [POST] [in /Users/rlheureu/Coding/microblog-0.15/venv/lib/python2.7/site-packages/flask/app.py:1560]
Traceback (most recent call last):
  File "/Users/rlheureu/Coding/microblog-0.15/venv/lib/python2.7/site-packages/flask/app.py", line 1982, in wsgi_app
    response = self.full_dispatch_request()
  File "/Users/rlheureu/Coding/microblog-0.15/venv/lib/python2.7/site-packages/flask/app.py", line 1614, in full_dispatch_request
    rv = self.handle_user_exception(e)
  File "/Users/rlheureu/Coding/microblog-0.15/venv/lib/python2.7/site-packages/flask/app.py", line 1517, in handle_user_exception
    reraise(exc_type, exc_value, tb)
  File "/Users/rlheureu/Coding/microblog-0.15/venv/lib/python2.7/site-packages/flask/app.py", line 1612, in full_dispatch_request
    rv = self.dispatch_request()
  File "/Users/rlheureu/Coding/microblog-0.15/venv/lib/python2.7/site-packages/flask/app.py", line 1598, in dispatch_request
    return self.view_functions[rule.endpoint](**req.view_args)
  File "/Users/rlheureu/Coding/microblog-0.15/venv/lib/python2.7/site-packages/flask_httpauth.py", line 93, in decorated
    return f(*args, **kwargs)
  File "/Users/rlheureu/Coding/microblog-0.15/app/api/posts.py", line 49, in create_post
    if ['user_id'] not in data:
TypeError: unhashable type: 'list'
2018-02-06 16:04:13,139 INFO: Microblog startup [in /Users/rlheureu/Coding/microblog-0.15/app/__init__.py:85]
2018-02-06 16:04:15,908 ERROR: Exception on /api/posts [POST] [in /Users/rlheureu/Coding/microblog-0.15/venv/lib/python2.7/site-packages/flask/app.py:1560]
Traceback (most recent call last):
  File "/Users/rlheureu/Coding/microblog-0.15/venv/lib/python2.7/site-packages/flask/app.py", line 1982, in wsgi_app
    response = self.full_dispatch_request()
  File "/Users/rlheureu/Coding/microblog-0.15/venv/lib/python2.7/site-packages/flask/app.py", line 1614, in full_dispatch_request
    rv = self.handle_user_exception(e)
  File "/Users/rlheureu/Coding/microblog-0.15/venv/lib/python2.7/site-packages/flask/app.py", line 1517, in handle_user_exception
    reraise(exc_type, exc_value, tb)
  File "/Users/rlheureu/Coding/microblog-0.15/venv/lib/python2.7/site-packages/flask/app.py", line 1612, in full_dispatch_request
    rv = self.dispatch_request()
  File "/Users/rlheureu/Coding/microblog-0.15/venv/lib/python2.7/site-packages/flask/app.py", line 1598, in dispatch_request
    return self.view_functions[rule.endpoint](**req.view_args)
  File "/Users/rlheureu/Coding/microblog-0.15/venv/lib/python2.7/site-packages/flask_httpauth.py", line 93, in decorated
    return f(*args, **kwargs)
  File "/Users/rlheureu/Coding/microblog-0.15/app/api/posts.py", line 50, in create_post
    setattr(['user_id'], user.id)
TypeError: setattr expected 3 arguments, got 2
2018-02-06 16:04:46,207 INFO: Microblog startup [in /Users/rlheureu/Coding/microblog-0.15/app/__init__.py:85]
2018-02-06 16:04:48,863 ERROR: Exception on /api/posts [POST] [in /Users/rlheureu/Coding/microblog-0.15/venv/lib/python2.7/site-packages/flask/app.py:1560]
Traceback (most recent call last):
  File "/Users/rlheureu/Coding/microblog-0.15/venv/lib/python2.7/site-packages/flask/app.py", line 1982, in wsgi_app
    response = self.full_dispatch_request()
  File "/Users/rlheureu/Coding/microblog-0.15/venv/lib/python2.7/site-packages/flask/app.py", line 1614, in full_dispatch_request
    rv = self.handle_user_exception(e)
  File "/Users/rlheureu/Coding/microblog-0.15/venv/lib/python2.7/site-packages/flask/app.py", line 1517, in handle_user_exception
    reraise(exc_type, exc_value, tb)
  File "/Users/rlheureu/Coding/microblog-0.15/venv/lib/python2.7/site-packages/flask/app.py", line 1612, in full_dispatch_request
    rv = self.dispatch_request()
  File "/Users/rlheureu/Coding/microblog-0.15/venv/lib/python2.7/site-packages/flask/app.py", line 1598, in dispatch_request
    return self.view_functions[rule.endpoint](**req.view_args)
  File "/Users/rlheureu/Coding/microblog-0.15/venv/lib/python2.7/site-packages/flask_httpauth.py", line 93, in decorated
    return f(*args, **kwargs)
  File "/Users/rlheureu/Coding/microblog-0.15/app/api/posts.py", line 50, in create_post
    setattr(data,['user_id'], user.id)
TypeError: attribute name must be string, not 'list'
2018-02-06 16:05:45,666 INFO: Microblog startup [in /Users/rlheureu/Coding/microblog-0.15/app/__init__.py:85]
2018-02-06 16:05:48,971 ERROR: Exception on /api/posts [POST] [in /Users/rlheureu/Coding/microblog-0.15/venv/lib/python2.7/site-packages/flask/app.py:1560]
Traceback (most recent call last):
  File "/Users/rlheureu/Coding/microblog-0.15/venv/lib/python2.7/site-packages/flask/app.py", line 1982, in wsgi_app
    response = self.full_dispatch_request()
  File "/Users/rlheureu/Coding/microblog-0.15/venv/lib/python2.7/site-packages/flask/app.py", line 1614, in full_dispatch_request
    rv = self.handle_user_exception(e)
  File "/Users/rlheureu/Coding/microblog-0.15/venv/lib/python2.7/site-packages/flask/app.py", line 1517, in handle_user_exception
    reraise(exc_type, exc_value, tb)
  File "/Users/rlheureu/Coding/microblog-0.15/venv/lib/python2.7/site-packages/flask/app.py", line 1612, in full_dispatch_request
    rv = self.dispatch_request()
  File "/Users/rlheureu/Coding/microblog-0.15/venv/lib/python2.7/site-packages/flask/app.py", line 1598, in dispatch_request
    return self.view_functions[rule.endpoint](**req.view_args)
  File "/Users/rlheureu/Coding/microblog-0.15/venv/lib/python2.7/site-packages/flask_httpauth.py", line 93, in decorated
    return f(*args, **kwargs)
  File "/Users/rlheureu/Coding/microblog-0.15/app/api/posts.py", line 50, in create_post
    setattr(data,'user_id', user.id)
AttributeError: 'dict' object has no attribute 'user_id'
