2018-02-02 09:43:48,873 ERROR: Unhandled exception [in ./app/tasks.py:47]
Traceback (most recent call last):
  File "./app/tasks.py", line 44, in export_posts
    sync=True)
  File "./app/email.py", line 21, in send_email
    mail.send(msg)
  File "/Users/rlheureu/Coding/microblog-0.15/venv/lib/python2.7/site-packages/flask_mail.py", line 492, in send
    message.send(connection)
  File "/Users/rlheureu/Coding/microblog-0.15/venv/lib/python2.7/site-packages/flask_mail.py", line 152, in __exit__
    self.host.quit()
  File "/System/Library/Frameworks/Python.framework/Versions/2.7/lib/python2.7/smtplib.py", line 767, in quit
    res = self.docmd("quit")
  File "/System/Library/Frameworks/Python.framework/Versions/2.7/lib/python2.7/smtplib.py", line 393, in docmd
    self.putcmd(cmd, args)
  File "/System/Library/Frameworks/Python.framework/Versions/2.7/lib/python2.7/smtplib.py", line 341, in putcmd
    self.send(str)
  File "/System/Library/Frameworks/Python.framework/Versions/2.7/lib/python2.7/smtplib.py", line 333, in send
    raise SMTPServerDisconnected('please run connect() first')
SMTPServerDisconnected: please run connect() first
2018-02-02 10:09:32,033 INFO: Microblog startup [in /Users/rlheureu/Coding/microblog-0.15/app/__init__.py:82]
2018-02-02 10:09:49,736 INFO: Microblog startup [in ./app/__init__.py:82]
2018-02-02 10:09:54,842 ERROR: Unhandled exception [in ./app/tasks.py:47]
Traceback (most recent call last):
  File "./app/tasks.py", line 44, in export_posts
    sync=True)
  File "./app/email.py", line 21, in send_email
    mail.send(msg)
  File "/Users/rlheureu/Coding/microblog-0.15/venv/lib/python2.7/site-packages/flask_mail.py", line 492, in send
    message.send(connection)
  File "/Users/rlheureu/Coding/microblog-0.15/venv/lib/python2.7/site-packages/flask_mail.py", line 152, in __exit__
    self.host.quit()
  File "/System/Library/Frameworks/Python.framework/Versions/2.7/lib/python2.7/smtplib.py", line 767, in quit
    res = self.docmd("quit")
  File "/System/Library/Frameworks/Python.framework/Versions/2.7/lib/python2.7/smtplib.py", line 393, in docmd
    self.putcmd(cmd, args)
  File "/System/Library/Frameworks/Python.framework/Versions/2.7/lib/python2.7/smtplib.py", line 341, in putcmd
    self.send(str)
  File "/System/Library/Frameworks/Python.framework/Versions/2.7/lib/python2.7/smtplib.py", line 333, in send
    raise SMTPServerDisconnected('please run connect() first')
SMTPServerDisconnected: please run connect() first
2018-02-02 10:11:10,929 INFO: Microblog startup [in /Users/rlheureu/Coding/microblog-0.15/app/__init__.py:82]
2018-02-02 10:25:01,608 INFO: Microblog startup [in /Users/rlheureu/Coding/microblog-0.15/app/__init__.py:82]
2018-02-02 10:25:16,837 INFO: Microblog startup [in /Users/rlheureu/Coding/microblog-0.15/app/__init__.py:82]
2018-02-02 10:25:23,899 INFO: Microblog startup [in ./app/__init__.py:82]
2018-02-02 10:25:28,994 ERROR: Unhandled exception [in ./app/tasks.py:47]
Traceback (most recent call last):
  File "./app/tasks.py", line 44, in export_posts
    sync=True)
  File "./app/email.py", line 21, in send_email
    mail.send(msg)
  File "/Users/rlheureu/Coding/microblog-0.15/venv/lib/python2.7/site-packages/flask_mail.py", line 492, in send
    message.send(connection)
  File "/Users/rlheureu/Coding/microblog-0.15/venv/lib/python2.7/site-packages/flask_mail.py", line 152, in __exit__
    self.host.quit()
  File "/System/Library/Frameworks/Python.framework/Versions/2.7/lib/python2.7/smtplib.py", line 767, in quit
    res = self.docmd("quit")
  File "/System/Library/Frameworks/Python.framework/Versions/2.7/lib/python2.7/smtplib.py", line 393, in docmd
    self.putcmd(cmd, args)
  File "/System/Library/Frameworks/Python.framework/Versions/2.7/lib/python2.7/smtplib.py", line 341, in putcmd
    self.send(str)
  File "/System/Library/Frameworks/Python.framework/Versions/2.7/lib/python2.7/smtplib.py", line 333, in send
    raise SMTPServerDisconnected('please run connect() first')
SMTPServerDisconnected: please run connect() first
2018-02-02 10:30:08,485 INFO: Microblog startup [in ./app/__init__.py:82]
2018-02-02 10:30:13,576 ERROR: Unhandled exception [in ./app/tasks.py:47]
Traceback (most recent call last):
  File "./app/tasks.py", line 44, in export_posts
    sync=True)
  File "./app/email.py", line 21, in send_email
    mail.send(msg)
  File "/Users/rlheureu/Coding/microblog-0.15/venv/lib/python2.7/site-packages/flask_mail.py", line 492, in send
    message.send(connection)
  File "/Users/rlheureu/Coding/microblog-0.15/venv/lib/python2.7/site-packages/flask_mail.py", line 152, in __exit__
    self.host.quit()
  File "/System/Library/Frameworks/Python.framework/Versions/2.7/lib/python2.7/smtplib.py", line 767, in quit
    res = self.docmd("quit")
  File "/System/Library/Frameworks/Python.framework/Versions/2.7/lib/python2.7/smtplib.py", line 393, in docmd
    self.putcmd(cmd, args)
  File "/System/Library/Frameworks/Python.framework/Versions/2.7/lib/python2.7/smtplib.py", line 341, in putcmd
    self.send(str)
  File "/System/Library/Frameworks/Python.framework/Versions/2.7/lib/python2.7/smtplib.py", line 333, in send
    raise SMTPServerDisconnected('please run connect() first')
SMTPServerDisconnected: please run connect() first
2018-02-02 10:30:43,302 INFO: Microblog startup [in /Users/rlheureu/Coding/microblog-0.15/app/__init__.py:82]
2018-02-02 10:30:49,532 INFO: Microblog startup [in ./app/__init__.py:82]
2018-02-02 10:43:30,122 INFO: Microblog startup [in /Users/rlheureu/Coding/microblog-0.15/app/__init__.py:82]
2018-02-02 10:43:39,895 INFO: Microblog startup [in /Users/rlheureu/Coding/microblog-0.15/app/__init__.py:82]
2018-02-02 10:44:02,050 INFO: Microblog startup [in /Users/rlheureu/Coding/microblog-0.15/app/__init__.py:82]
2018-02-02 10:44:21,123 INFO: Microblog startup [in ./app/__init__.py:82]
2018-02-02 10:45:35,140 INFO: Microblog startup [in /Users/rlheureu/Coding/microblog-0.15/app/__init__.py:82]
2018-02-02 10:48:08,785 INFO: Microblog startup [in /Users/rlheureu/Coding/microblog-0.15/app/__init__.py:82]
2018-02-02 10:48:17,479 INFO: Microblog startup [in ./app/__init__.py:82]
2018-02-02 10:50:41,528 INFO: Microblog startup [in /Users/rlheureu/Coding/microblog-0.15/app/__init__.py:82]
2018-02-02 10:50:54,422 INFO: Microblog startup [in ./app/__init__.py:82]
2018-02-02 10:54:13,848 INFO: Microblog startup [in /Users/rlheureu/Coding/microblog-0.15/app/__init__.py:82]
2018-02-02 10:54:20,307 INFO: Microblog startup [in ./app/__init__.py:82]
2018-02-05 12:39:16,327 INFO: Microblog startup [in /Users/rlheureu/Coding/microblog-0.15/app/__init__.py:85]
2018-02-05 12:40:49,280 INFO: Microblog startup [in /Users/rlheureu/Coding/microblog-0.15/app/__init__.py:85]
2018-02-05 12:43:49,693 INFO: Microblog startup [in /Users/rlheureu/Coding/microblog-0.15/app/__init__.py:85]
2018-02-05 12:43:56,080 ERROR: Exception on /api/users [GET] [in /Users/rlheureu/Coding/microblog-0.15/venv/lib/python2.7/site-packages/flask/app.py:1560]
Traceback (most recent call last):
  File "/Users/rlheureu/Coding/microblog-0.15/venv/lib/python2.7/site-packages/flask/app.py", line 1982, in wsgi_app
    response = self.full_dispatch_request()
  File "/Users/rlheureu/Coding/microblog-0.15/venv/lib/python2.7/site-packages/flask/app.py", line 1614, in full_dispatch_request
    rv = self.handle_user_exception(e)
  File "/Users/rlheureu/Coding/microblog-0.15/venv/lib/python2.7/site-packages/flask/app.py", line 1517, in handle_user_exception
    reraise(exc_type, exc_value, tb)
  File "/Users/rlheureu/Coding/microblog-0.15/venv/lib/python2.7/site-packages/flask/app.py", line 1612, in full_dispatch_request
    rv = self.dispatch_request()
  File "/Users/rlheureu/Coding/microblog-0.15/venv/lib/python2.7/site-packages/flask/app.py", line 1598, in dispatch_request
    return self.view_functions[rule.endpoint](**req.view_args)
  File "/Users/rlheureu/Coding/microblog-0.15/app/api/users.py", line 11, in get_users
    page = request.args.get('page', 1, type=int)
NameError: global name 'request' is not defined
2018-02-05 12:44:46,127 INFO: Microblog startup [in /Users/rlheureu/Coding/microblog-0.15/app/__init__.py:85]
2018-02-05 14:25:28,684 INFO: Microblog startup [in /Users/rlheureu/Coding/microblog-0.15/app/__init__.py:85]
2018-02-05 14:26:54,282 ERROR: Exception on /api/users [POST] [in /Users/rlheureu/Coding/microblog-0.15/venv/lib/python2.7/site-packages/flask/app.py:1560]
Traceback (most recent call last):
  File "/Users/rlheureu/Coding/microblog-0.15/venv/lib/python2.7/site-packages/flask/app.py", line 1982, in wsgi_app
    response = self.full_dispatch_request()
  File "/Users/rlheureu/Coding/microblog-0.15/venv/lib/python2.7/site-packages/flask/app.py", line 1614, in full_dispatch_request
    rv = self.handle_user_exception(e)
  File "/Users/rlheureu/Coding/microblog-0.15/venv/lib/python2.7/site-packages/flask/app.py", line 1517, in handle_user_exception
    reraise(exc_type, exc_value, tb)
  File "/Users/rlheureu/Coding/microblog-0.15/venv/lib/python2.7/site-packages/flask/app.py", line 1612, in full_dispatch_request
    rv = self.dispatch_request()
  File "/Users/rlheureu/Coding/microblog-0.15/venv/lib/python2.7/site-packages/flask/app.py", line 1598, in dispatch_request
    return self.view_functions[rule.endpoint](**req.view_args)
  File "/Users/rlheureu/Coding/microblog-0.15/app/api/users.py", line 45, in create_user
    response = jsonify(user.to_dict())
  File "/Users/rlheureu/Coding/microblog-0.15/app/models.py", line 171, in to_dict
    'last_seen': self.last_seen.isoformat() + 'Z',
AttributeError: 'NoneType' object has no attribute 'isoformat'
