2017-12-19 15:57:44,907 ERROR: Exception on /favicon.ico [GET] [in /Users/rlheureu/Coding/microblog-0.15/venv/lib/python2.7/site-packages/flask/app.py:1560]
Traceback (most recent call last):
  File "/Users/rlheureu/Coding/microblog-0.15/venv/lib/python2.7/site-packages/flask/app.py", line 1982, in wsgi_app
    response = self.full_dispatch_request()
  File "/Users/rlheureu/Coding/microblog-0.15/venv/lib/python2.7/site-packages/flask/app.py", line 1614, in full_dispatch_request
    rv = self.handle_user_exception(e)
  File "/Users/rlheureu/Coding/microblog-0.15/venv/lib/python2.7/site-packages/flask/app.py", line 1517, in handle_user_exception
    reraise(exc_type, exc_value, tb)
  File "/Users/rlheureu/Coding/microblog-0.15/venv/lib/python2.7/site-packages/flask/app.py", line 1610, in full_dispatch_request
    rv = self.preprocess_request()
  File "/Users/rlheureu/Coding/microblog-0.15/venv/lib/python2.7/site-packages/flask/app.py", line 1831, in preprocess_request
    rv = func()
  File "/Users/rlheureu/Coding/microblog-0.15/app/main/routes.py", line 16, in before_request
    if current_user.is_authenticated:
  File "/Users/rlheureu/Coding/microblog-0.15/venv/lib/python2.7/site-packages/werkzeug/local.py", line 347, in __getattr__
    return getattr(self._get_current_object(), name)
  File "/Users/rlheureu/Coding/microblog-0.15/venv/lib/python2.7/site-packages/werkzeug/local.py", line 306, in _get_current_object
    return self.__local()
  File "/Users/rlheureu/Coding/microblog-0.15/venv/lib/python2.7/site-packages/flask_login/utils.py", line 26, in <lambda>
    current_user = LocalProxy(lambda: _get_user())
  File "/Users/rlheureu/Coding/microblog-0.15/venv/lib/python2.7/site-packages/flask_login/utils.py", line 302, in _get_user
    current_app.login_manager._load_user()
  File "/Users/rlheureu/Coding/microblog-0.15/venv/lib/python2.7/site-packages/flask_login/login_manager.py", line 317, in _load_user
    return self.reload_user()
  File "/Users/rlheureu/Coding/microblog-0.15/venv/lib/python2.7/site-packages/flask_login/login_manager.py", line 279, in reload_user
    user = self.user_callback(user_id)
  File "/Users/rlheureu/Coding/microblog-0.15/app/models.py", line 83, in load_user
    return User.query.get(int(id))
  File "/Users/rlheureu/Coding/microblog-0.15/venv/lib/python2.7/site-packages/sqlalchemy/orm/query.py", line 864, in get
    return self._get_impl(ident, loading.load_on_ident)
  File "/Users/rlheureu/Coding/microblog-0.15/venv/lib/python2.7/site-packages/sqlalchemy/orm/query.py", line 897, in _get_impl
    return fallback_fn(self, key)
  File "/Users/rlheureu/Coding/microblog-0.15/venv/lib/python2.7/site-packages/sqlalchemy/orm/loading.py", line 223, in load_on_ident
    return q.one()
  File "/Users/rlheureu/Coding/microblog-0.15/venv/lib/python2.7/site-packages/sqlalchemy/orm/query.py", line 2814, in one
    ret = self.one_or_none()
  File "/Users/rlheureu/Coding/microblog-0.15/venv/lib/python2.7/site-packages/sqlalchemy/orm/query.py", line 2784, in one_or_none
    ret = list(self)
  File "/Users/rlheureu/Coding/microblog-0.15/venv/lib/python2.7/site-packages/sqlalchemy/orm/query.py", line 2855, in __iter__
    return self._execute_and_instances(context)
  File "/Users/rlheureu/Coding/microblog-0.15/venv/lib/python2.7/site-packages/sqlalchemy/orm/query.py", line 2878, in _execute_and_instances
    result = conn.execute(querycontext.statement, self._params)
  File "/Users/rlheureu/Coding/microblog-0.15/venv/lib/python2.7/site-packages/sqlalchemy/engine/base.py", line 945, in execute
    return meth(self, multiparams, params)
  File "/Users/rlheureu/Coding/microblog-0.15/venv/lib/python2.7/site-packages/sqlalchemy/sql/elements.py", line 263, in _execute_on_connection
    return connection._execute_clauseelement(self, multiparams, params)
  File "/Users/rlheureu/Coding/microblog-0.15/venv/lib/python2.7/site-packages/sqlalchemy/engine/base.py", line 1053, in _execute_clauseelement
    compiled_sql, distilled_params
  File "/Users/rlheureu/Coding/microblog-0.15/venv/lib/python2.7/site-packages/sqlalchemy/engine/base.py", line 1189, in _execute_context
    context)
  File "/Users/rlheureu/Coding/microblog-0.15/venv/lib/python2.7/site-packages/sqlalchemy/engine/base.py", line 1402, in _handle_dbapi_exception
    exc_info
  File "/Users/rlheureu/Coding/microblog-0.15/venv/lib/python2.7/site-packages/sqlalchemy/util/compat.py", line 203, in raise_from_cause
    reraise(type(exception), exception, tb=exc_tb, cause=cause)
  File "/Users/rlheureu/Coding/microblog-0.15/venv/lib/python2.7/site-packages/sqlalchemy/engine/base.py", line 1182, in _execute_context
    context)
  File "/Users/rlheureu/Coding/microblog-0.15/venv/lib/python2.7/site-packages/sqlalchemy/engine/default.py", line 470, in do_execute
    cursor.execute(statement, parameters)
OperationalError: (sqlite3.OperationalError) no such table: user [SQL: u'SELECT user.id AS user_id, user.username AS user_username, user.email AS user_email, user.password_hash AS user_password_hash, user.about_me AS user_about_me, user.last_seen AS user_last_seen \nFROM user \nWHERE user.id = ?'] [parameters: (1,)]
