2018-02-06 17:19:45,527 ERROR: Exception on /api/posts/Rob/ [GET] [in /Users/rlheureu/Coding/microblog-0.15/venv/lib/python2.7/site-packages/flask/app.py:1560]
Traceback (most recent call last):
  File "/Users/rlheureu/Coding/microblog-0.15/venv/lib/python2.7/site-packages/flask/app.py", line 1982, in wsgi_app
    response = self.full_dispatch_request()
  File "/Users/rlheureu/Coding/microblog-0.15/venv/lib/python2.7/site-packages/flask/app.py", line 1614, in full_dispatch_request
    rv = self.handle_user_exception(e)
  File "/Users/rlheureu/Coding/microblog-0.15/venv/lib/python2.7/site-packages/flask/app.py", line 1517, in handle_user_exception
    reraise(exc_type, exc_value, tb)
  File "/Users/rlheureu/Coding/microblog-0.15/venv/lib/python2.7/site-packages/flask/app.py", line 1612, in full_dispatch_request
    rv = self.dispatch_request()
  File "/Users/rlheureu/Coding/microblog-0.15/venv/lib/python2.7/site-packages/flask/app.py", line 1598, in dispatch_request
    return self.view_functions[rule.endpoint](**req.view_args)
  File "/Users/rlheureu/Coding/microblog-0.15/app/api/posts.py", line 31, in get_user_posts
    data = Post.to_collection_dict(Post.query.filter_by(user_id=user.id), page, per_page, 'api.get_user_posts', username=username)
  File "/Users/rlheureu/Coding/microblog-0.15/app/models.py", line 16, in to_collection_dict
    'items': [item.to_dict() for item in resources.items],
  File "/Users/rlheureu/Coding/microblog-0.15/app/models.py", line 240, in to_dict
    'posts': url_for('api.get_user_posts', id=self.user_id)
  File "/Users/rlheureu/Coding/microblog-0.15/venv/lib/python2.7/site-packages/flask/helpers.py", line 333, in url_for
    return appctx.app.handle_url_build_error(error, endpoint, values)
  File "/Users/rlheureu/Coding/microblog-0.15/venv/lib/python2.7/site-packages/flask/app.py", line 1805, in handle_url_build_error
    reraise(exc_type, exc_value, tb)
  File "/Users/rlheureu/Coding/microblog-0.15/venv/lib/python2.7/site-packages/flask/helpers.py", line 323, in url_for
    force_external=external)
  File "/Users/rlheureu/Coding/microblog-0.15/venv/lib/python2.7/site-packages/werkzeug/routing.py", line 1768, in build
    raise BuildError(endpoint, values, method, self)
BuildError: Could not build url for endpoint 'api.get_user_posts' with values ['id']. Did you forget to specify values ['username']?
2018-02-06 17:21:47,985 INFO: Microblog startup [in /Users/rlheureu/Coding/microblog-0.15/app/__init__.py:85]
2018-02-06 17:21:50,879 ERROR: Exception on /api/posts/Rob/ [GET] [in /Users/rlheureu/Coding/microblog-0.15/venv/lib/python2.7/site-packages/flask/app.py:1560]
Traceback (most recent call last):
  File "/Users/rlheureu/Coding/microblog-0.15/venv/lib/python2.7/site-packages/flask/app.py", line 1982, in wsgi_app
    response = self.full_dispatch_request()
  File "/Users/rlheureu/Coding/microblog-0.15/venv/lib/python2.7/site-packages/flask/app.py", line 1614, in full_dispatch_request
    rv = self.handle_user_exception(e)
  File "/Users/rlheureu/Coding/microblog-0.15/venv/lib/python2.7/site-packages/flask/app.py", line 1517, in handle_user_exception
    reraise(exc_type, exc_value, tb)
  File "/Users/rlheureu/Coding/microblog-0.15/venv/lib/python2.7/site-packages/flask/app.py", line 1612, in full_dispatch_request
    rv = self.dispatch_request()
  File "/Users/rlheureu/Coding/microblog-0.15/venv/lib/python2.7/site-packages/flask/app.py", line 1598, in dispatch_request
    return self.view_functions[rule.endpoint](**req.view_args)
  File "/Users/rlheureu/Coding/microblog-0.15/app/api/posts.py", line 31, in get_user_posts
    data = Post.to_collection_dict(Post.query.filter_by(user_id=user.id), page, per_page, 'api.get_user_posts', username=user.username)
  File "/Users/rlheureu/Coding/microblog-0.15/app/models.py", line 16, in to_collection_dict
    'items': [item.to_dict() for item in resources.items],
  File "/Users/rlheureu/Coding/microblog-0.15/app/models.py", line 240, in to_dict
    'posts': url_for('api.get_user_posts', id=self.user_id)
  File "/Users/rlheureu/Coding/microblog-0.15/venv/lib/python2.7/site-packages/flask/helpers.py", line 333, in url_for
    return appctx.app.handle_url_build_error(error, endpoint, values)
  File "/Users/rlheureu/Coding/microblog-0.15/venv/lib/python2.7/site-packages/flask/app.py", line 1805, in handle_url_build_error
    reraise(exc_type, exc_value, tb)
  File "/Users/rlheureu/Coding/microblog-0.15/venv/lib/python2.7/site-packages/flask/helpers.py", line 323, in url_for
    force_external=external)
  File "/Users/rlheureu/Coding/microblog-0.15/venv/lib/python2.7/site-packages/werkzeug/routing.py", line 1768, in build
    raise BuildError(endpoint, values, method, self)
BuildError: Could not build url for endpoint 'api.get_user_posts' with values ['id']. Did you forget to specify values ['username']?
2018-02-06 17:22:15,657 INFO: Microblog startup [in /Users/rlheureu/Coding/microblog-0.15/app/__init__.py:85]
2018-02-06 17:22:26,993 ERROR: Exception on /api/posts/Rob/ [GET] [in /Users/rlheureu/Coding/microblog-0.15/venv/lib/python2.7/site-packages/flask/app.py:1560]
Traceback (most recent call last):
  File "/Users/rlheureu/Coding/microblog-0.15/venv/lib/python2.7/site-packages/flask/app.py", line 1982, in wsgi_app
    response = self.full_dispatch_request()
  File "/Users/rlheureu/Coding/microblog-0.15/venv/lib/python2.7/site-packages/flask/app.py", line 1614, in full_dispatch_request
    rv = self.handle_user_exception(e)
  File "/Users/rlheureu/Coding/microblog-0.15/venv/lib/python2.7/site-packages/flask/app.py", line 1517, in handle_user_exception
    reraise(exc_type, exc_value, tb)
  File "/Users/rlheureu/Coding/microblog-0.15/venv/lib/python2.7/site-packages/flask/app.py", line 1612, in full_dispatch_request
    rv = self.dispatch_request()
  File "/Users/rlheureu/Coding/microblog-0.15/venv/lib/python2.7/site-packages/flask/app.py", line 1598, in dispatch_request
    return self.view_functions[rule.endpoint](**req.view_args)
  File "/Users/rlheureu/Coding/microblog-0.15/app/api/posts.py", line 22, in get_user_posts
    user = User.query.filter_by(username=user.username).first()
UnboundLocalError: local variable 'user' referenced before assignment
2018-02-06 17:23:35,719 INFO: Microblog startup [in /Users/rlheureu/Coding/microblog-0.15/app/__init__.py:85]
2018-02-06 17:23:37,464 ERROR: Exception on /api/posts/Rob/ [GET] [in /Users/rlheureu/Coding/microblog-0.15/venv/lib/python2.7/site-packages/flask/app.py:1560]
Traceback (most recent call last):
  File "/Users/rlheureu/Coding/microblog-0.15/venv/lib/python2.7/site-packages/flask/app.py", line 1982, in wsgi_app
    response = self.full_dispatch_request()
  File "/Users/rlheureu/Coding/microblog-0.15/venv/lib/python2.7/site-packages/flask/app.py", line 1614, in full_dispatch_request
    rv = self.handle_user_exception(e)
  File "/Users/rlheureu/Coding/microblog-0.15/venv/lib/python2.7/site-packages/flask/app.py", line 1517, in handle_user_exception
    reraise(exc_type, exc_value, tb)
  File "/Users/rlheureu/Coding/microblog-0.15/venv/lib/python2.7/site-packages/flask/app.py", line 1612, in full_dispatch_request
    rv = self.dispatch_request()
  File "/Users/rlheureu/Coding/microblog-0.15/venv/lib/python2.7/site-packages/flask/app.py", line 1598, in dispatch_request
    return self.view_functions[rule.endpoint](**req.view_args)
  File "/Users/rlheureu/Coding/microblog-0.15/app/api/posts.py", line 31, in get_user_posts
    data = Post.to_collection_dict(Post.query.filter_by(user_id=user.id), page, per_page, 'api.get_user_posts', username=user.username)
  File "/Users/rlheureu/Coding/microblog-0.15/app/models.py", line 16, in to_collection_dict
    'items': [item.to_dict() for item in resources.items],
  File "/Users/rlheureu/Coding/microblog-0.15/app/models.py", line 240, in to_dict
    'posts': url_for('api.get_user_posts', id=self.user_id)
  File "/Users/rlheureu/Coding/microblog-0.15/venv/lib/python2.7/site-packages/flask/helpers.py", line 333, in url_for
    return appctx.app.handle_url_build_error(error, endpoint, values)
  File "/Users/rlheureu/Coding/microblog-0.15/venv/lib/python2.7/site-packages/flask/app.py", line 1805, in handle_url_build_error
    reraise(exc_type, exc_value, tb)
  File "/Users/rlheureu/Coding/microblog-0.15/venv/lib/python2.7/site-packages/flask/helpers.py", line 323, in url_for
    force_external=external)
  File "/Users/rlheureu/Coding/microblog-0.15/venv/lib/python2.7/site-packages/werkzeug/routing.py", line 1768, in build
    raise BuildError(endpoint, values, method, self)
BuildError: Could not build url for endpoint 'api.get_user_posts' with values ['id']. Did you forget to specify values ['username']?
2018-02-06 17:25:57,716 INFO: Microblog startup [in /Users/rlheureu/Coding/microblog-0.15/app/__init__.py:85]
